Workbook
Name UPDATE: 'Data Sheet'!$E$1

Sheet Sheet3
A1: VALUE
A2: 6.8411153e+09 | C2: Top Shareholder | D2: Shares Holding | E2: Share Price (₹)
A3: 7.3777692e+09 | C3: Tata Sons Pvt. Ltd. | D3: 2595499419 | E3: Current TCS Price | M3: Top Shareholder | N3: Share % | O3: Shares Holding | P3: Share Price (₹) | Q3: Market Value (₹ Cr.)
A4: 1.0269563e+10 | C4: LIC of India | D4: 199553451 | E4: Current TCS Price | N4: 0.7174 | P4: Current TCS Price | Q4: {=Shares * Share Price} -> #NAME?
A5: 1.2055719e+10 | C5: SBI Mutual Fund | D5: 45239395 | E5: Current TCS Price | N5: 0.0552 | P5: Current TCS Price | Q5: {=Shares * Share Price} -> #NAME?
A6: 1.7571237e+10 | C6: ICICI Prudential MF | D6: 38172688 | E6: Current TCS Price | N6: 0.0125 | P6: Current TCS Price | Q6: {=Shares * Share Price} -> #NAME?
A7: 19711786830 | C7: NPS Trust | D7: 28525843 | E7: Current TCS Price | N7: 0.0106 | P7: Current TCS Price | Q7: {=Shares * Share Price} -> #NAME?
A8: 9.2162958e+09 | N8: 0.0079 | P8: Current TCS Price | Q8: {=Shares * Share Price} -> #NAME?
A9: 7.2136561e+09
A10: 5.5852587e+09
A11: 3.5378399e+09
A12: 5.3120746e+09
A13: 4.9716236e+09
A14: 1.2666031e+10
A15: 1.1501045e+10
A16: 1.1854245e+10
A17: 2.100566e+10
A18: 2.6782359e+10
A19: 1.4020751e+10
A20: 7.748164e+09
... A23: 5.2936196e+09

Sheet Profit & Loss
A1: ='Data Sheet'!B1 -> TATA CONSULTANCY SERVICES LTD | H1: =UPDATE | M1: SCREENER.IN
A3: Narration | B3: ='Data Sheet'!B16 -> 42825 | C3: ='Data Sheet'!C16 -> 43190 | D3: ='Data Sheet'!D16 -> 43555 | E3: ='Data Sheet'!E16 -> 43921 | F3: ='Data Sheet'!F16 -> 44286 | G3: ='Data Sheet'!G16 -> 44651 | H3: ='Data Sheet'!H16 -> 45016 | I3: ='Data Sheet'!I16 -> 45382 | ... K3: ='Data Sheet'!K16 -> 46112 | L3: Trailing | M3: Best Case | N3: Worst Case
A4: Sales | B4: ='Data Sheet'!B17 -> 117966 | C4: ='Data Sheet'!C17 -> 123104 | D4: ='Data Sheet'!D17 -> 146463 | E4: ='Data Sheet'!E17 -> 156949 | F4: ='Data Sheet'!F17 -> 164177 | G4: ='Data Sheet'!G17 -> 191754 | H4: ='Data Sheet'!H17 -> 225458 | I4: ='Data Sheet'!I17 -> 240893 | ... K4: ='Data Sheet'!K17 -> 267021 | L4: =SUM(Quarters!H4:K4) -> 275859 | M4: =$K4+M23*K4 -> 282513.15 | N4: =$K4+N23*L4 -> 279658.76
A5: Expenses | B5: =SUM('Data Sheet'!B18,'Data Sheet'!B20:B24, -1*'Data Sheet'!B19) -> 85655 | C5: =SUM('Data Sheet'!C18,'Data Sheet'!C20:C24, -1*'Data Sheet'!C19) -> 90588 | D5: =SUM('Data Sheet'!D18,'Data Sheet'!D20:D24, -1*'Data Sheet'!D19) -> 106957 | E5: =SUM('Data Sheet'!E18,'Data Sheet'!E20:E24, -1*'Data Sheet'!E19) -> 114840 | F5: =SUM('Data Sheet'!F18,'Data Sheet'!F20:F24, -1*'Data Sheet'!F19) -> 117631 | G5: =SUM('Data Sheet'!G18,'Data Sheet'!G20:G24, -1*'Data Sheet'!G19) -> 138697 | H5: =SUM('Data Sheet'!H18,'Data Sheet'!H20:H24, -1*'Data Sheet'!H19) -> 166199 | I5: =SUM('Data Sheet'!I18,'Data Sheet'!I20:I24, -1*'Data Sheet'!I19) -> 176597 | ... K5: =SUM('Data Sheet'!K18,'Data Sheet'!K20:K24, -1*'Data Sheet'!K19) -> 194623 | L5: =SUM(Quarters!H5:K5) -> 201780 | M5: =M4-M6 -> 206647.25 | N5: =N4-N6 -> 204873.92
A6: Operating Profit | B6: =B4-B5 -> 32311 | C6: =C4-C5 -> 32516 | D6: =D4-D5 -> 39506 | E6: =E4-E5 -> 42109 | F6: =F4-F5 -> 46546 | G6: =G4-G5 -> 53057 | H6: =H4-H5 -> 59259 | I6: =I4-I5 -> 64296 | ... K6: =K4-K5 -> 72398 | L6: =SUM(Quarters!H6:K6) -> 74079 | M6: =M4*M24 -> 75865.902 | N6: =N4*N24 -> 74784.84
A7: Other Income | B7: ='Data Sheet'!B25 -> 4221 | C7: ='Data Sheet'!C25 -> 3642 | D7: ='Data Sheet'!D25 -> 4311 | E7: ='Data Sheet'!E25 -> 4592 | F7: ='Data Sheet'!F25 -> 1916 | G7: ='Data Sheet'!G25 -> 4018 | H7: ='Data Sheet'!H25 -> 3449 | I7: ='Data Sheet'!I25 -> 3464 | ... K7: ='Data Sheet'!K25 -> -124 | L7: =SUM(Quarters!H7:K7) -> -884 | M7: 0 | N7: 0
A8: Depreciation | B8: ='Data Sheet'!B26 -> 1987 | C8: ='Data Sheet'!C26 -> 2014 | D8: ='Data Sheet'!D26 -> 2056 | E8: ='Data Sheet'!E26 -> 3529 | F8: ='Data Sheet'!F26 -> 4065 | G8: ='Data Sheet'!G26 -> 4604 | H8: ='Data Sheet'!H26 -> 5022 | I8: ='Data Sheet'!I26 -> 4985 | ... K8: ='Data Sheet'!K26 -> 5560 | L8: =SUM(Quarters!H8:K8) -> 5438 | M8: =+$L8 -> 5438 | N8: =+$L8 -> 5438
A9: Interest | B9: ='Data Sheet'!B27 -> 32 | C9: ='Data Sheet'!C27 -> 52 | D9: ='Data Sheet'!D27 -> 198 | E9: ='Data Sheet'!E27 -> 924 | F9: ='Data Sheet'!F27 -> 637 | G9: ='Data Sheet'!G27 -> 784 | H9: ='Data Sheet'!H27 -> 779 | I9: ='Data Sheet'!I27 -> 778 | ... K9: ='Data Sheet'!K27 -> 1227 | L9: =SUM(Quarters!H9:K9) -> 1305 | M9: =+$L9 -> 1305 | N9: =+$L9 -> 1305
A10: Profit before tax | B10: ='Data Sheet'!B28 -> 34513 | C10: ='Data Sheet'!C28 -> 34092 | D10: ='Data Sheet'!D28 -> 41563 | E10: ='Data Sheet'!E28 -> 42248 | F10: ='Data Sheet'!F28 -> 43760 | G10: ='Data Sheet'!G28 -> 51687 | H10: ='Data Sheet'!H28 -> 56907 | I10: ='Data Sheet'!I28 -> 61997 | ... K10: ='Data Sheet'!K28 -> 65487 | L10: =SUM(Quarters!H10:K10) -> 66452 | M10: =M6+M7-SUM(M8:M9) -> 69122.902 | N10: =N6+N7-SUM(N8:N9) -> 68041.84
A11: Tax | B11: ='Data Sheet'!B29 -> 8156 | C11: ='Data Sheet'!C29 -> 8212 | D11: ='Data Sheet'!D29 -> 10001 | E11: ='Data Sheet'!E29 -> 9801 | F11: ='Data Sheet'!F29 -> 11198 | G11: ='Data Sheet'!G29 -> 13238 | H11: ='Data Sheet'!H29 -> 14604 | I11: ='Data Sheet'!I29 -> 15898 | ... K11: ='Data Sheet'!K29 -> 16033 | L11: =SUM(Quarters!H11:K11) -> 16397 | M11: =IF($L10>0,$L11/$L10,0) -> 0.24674953 | N11: =IF($L10>0,$L11/$L10,0) -> 0.24674953
A12: Net profit | B12: ='Data Sheet'!B30 -> 26289 | C12: ='Data Sheet'!C30 -> 25826 | D12: ='Data Sheet'!D30 -> 31472 | E12: ='Data Sheet'!E30 -> 32340 | F12: ='Data Sheet'!F30 -> 32430 | G12: ='Data Sheet'!G30 -> 38327 | H12: ='Data Sheet'!H30 -> 42147 | I12: ='Data Sheet'!I30 -> 45908 | ... K12: ='Data Sheet'!K30 -> 49210 | L12: =SUM(Quarters!H12:K12) -> 49799 | M12: =M10-M11*M10 -> 52066.858 | N12: =N10-N11*N10 -> 51252.548
A13: EPS | B13: =IF('Data Sheet'!B93>0,B12/'Data Sheet'!B93,0) -> 66.708112 | C13: =IF('Data Sheet'!C93>0,C12/'Data Sheet'!C93,0) -> 67.455467 | D13: =IF('Data Sheet'!D93>0,D12/'Data Sheet'!D93,0) -> 83.871655 | E13: =IF('Data Sheet'!E93>0,E12/'Data Sheet'!E93,0) -> 86.184842 | F13: =IF('Data Sheet'!F93>0,F12/'Data Sheet'!F93,0) -> 87.669974 | G13: =IF('Data Sheet'!G93>0,G12/'Data Sheet'!G93,0) -> 104.74434 | H13: =IF('Data Sheet'!H93>0,H12/'Data Sheet'!H93,0) -> 115.18406 | I13: =IF('Data Sheet'!I93>0,I12/'Data Sheet'!I93,0) -> 126.88428 | ... K13: =IF('Data Sheet'!K93>0,K12/'Data Sheet'!K93,0) -> 136.01061 | L13: =IF('Data Sheet'!$B6>0,'Profit & Loss'!L12/'Data Sheet'!$B6,0) -> 137.63901 | M13: =IF('Data Sheet'!$B6>0,'Profit & Loss'!M12/'Data Sheet'!$B6,0) -> 143.90713 | N13: =IF('Data Sheet'!$B6>0,'Profit & Loss'!N12/'Data Sheet'!$B6,0) -> 141.65646
A14: Price to earning | B14: =IF(B15>0,B15/B13,"") -> 18.227168 | C14: =IF(C15>0,C15/C13,"") -> 21.118822 | D14: =IF(D15>0,D15/D13,"") -> 23.865631 | E14: =IF(E15>0,E15/E13,"") -> 21.188181 | F14: =IF(F15>0,F15/F13,"") -> 36.247872 | G14: =IF(G15>0,G15/G13,"") -> 35.705511 | H14: =IF(H15>0,H15/H13,"") -> 27.832844 | I14: =IF(I15>0,I15/I13,"") -> 30.549885 | ... K14: =IF(K15>0,K15/K13,"") -> 17.343499 | L14: =IF(L13>0,L15/L13,0) -> 17.186987 | M14: =M25 -> 22.988221 | N14: =N25 -> 17.186987
A15: Price | B15: ='Data Sheet'!B90 -> 1215.9 | C15: ='Data Sheet'!C90 -> 1424.58 | D15: ='Data Sheet'!D90 -> 2001.65 | E15: ='Data Sheet'!E90 -> 1826.1 | F15: ='Data Sheet'!F90 -> 3177.85 | G15: ='Data Sheet'!G90 -> 3739.95 | H15: ='Data Sheet'!H90 -> 3205.9 | I15: ='Data Sheet'!I90 -> 3876.3 | ... K15: ='Data Sheet'!K90 -> 2358.9 | L15: ='Data Sheet'!B8 -> 2365.6 | M15: =M13*M14 -> 3308.1689 | N15: =N13*N14 -> 2434.6478
A17: RATIOS:
A18: Dividend Payout | B18: =IF('Data Sheet'!B30>0, 'Data Sheet'!B31/'Data Sheet'!B30, 0) -> 0.35220054 | C18: =IF('Data Sheet'!C30>0, 'Data Sheet'!C31/'Data Sheet'!C30, 0) -> 0.36978239 | D18: =IF('Data Sheet'!D30>0, 'Data Sheet'!D31/'Data Sheet'!D30, 0) -> 0.3574606 | E18: =IF('Data Sheet'!E30>0, 'Data Sheet'!E31/'Data Sheet'!E30, 0) -> 0.84647495 | F18: =IF('Data Sheet'!F30>0, 'Data Sheet'!F31/'Data Sheet'!F30, 0) -> 0.43354918 | G18: =IF('Data Sheet'!G30>0, 'Data Sheet'!G31/'Data Sheet'!G30, 0) -> 0.41062436 | H18: =IF('Data Sheet'!H30>0, 'Data Sheet'!H31/'Data Sheet'!H30, 0) -> 0.99864759 | I18: =IF('Data Sheet'!I30>0, 'Data Sheet'!I31/'Data Sheet'!I30, 0) -> 0.57562952 | ... K18: =IF('Data Sheet'!K30>0, 'Data Sheet'!K31/'Data Sheet'!K30, 0) -> 0.80918512
A19: OPM | B19: =IF(B6>0,B6/B4,0) -> 0.27390095 | C19: =IF(C6>0,C6/C4,0) -> 0.26413439 | D19: =IF(D6>0,D6/D4,0) -> 0.26973365 | E19: =IF(E6>0,E6/E4,0) -> 0.26829734 | F19: =IF(F6>0,F6/F4,0) -> 0.28351109 | G19: =IF(G6>0,G6/G4,0) -> 0.27669305 | H19: =IF(H6>0,H6/H4,0) -> 0.26283831 | I19: =IF(I6>0,I6/I4,0) -> 0.26690688 | ... L19: =IF(L6>0,L6/L4,0) -> 0.26853936
G22: TRENDS: | H22: 10 YEARS | I22: 7 YEARS | J22: 5 YEARS | K22: 3 YEARS | L22: RECENT | M22: BEST | N22: WORST
G23: Sales Growth | H23: =IF(B4=0,"",POWER($K4/B4,1/9)-1) -> 0.095017227 | I23: =IF(D4=0,"",POWER($K4/D4,1/7)-1) -> 0.089581302 | J23: =IF(F4=0,"",POWER($K4/F4,1/5)-1) -> 0.10216501 | K23: =IF(H4=0,"",POWER($K4/H4, 1/3)-1) -> 0.058018486 | L23: =IF(ISERROR(MAX(IF(J4=0,"",(K4-J4)/J4),IF(K4=0,"",(L4-K4)/K4))),"",MAX(IF(J4=0,"",(K4-J4)/J4),IF(K4=0,"",(L4-K4)/K4))) -> 0.04581238 | M23: =MAX(K23:L23) -> 0.058018486 | N23: =MIN(H23:L23) -> 0.04581238
G24: OPM | H24: =IF(SUM(B4:$K$4)=0,"",SUMPRODUCT(B19:$K$19,B4:$K$4)/SUM(B4:$K$4)) -> 0.26965358 | I24: =IF(SUM(E4:$K$4)=0,"",SUMPRODUCT(E19:$K$19,E4:$K$4)/SUM(E4:$K$4)) -> 0.26976457 | J24: =IF(SUM(G4:$K$4)=0,"",SUMPRODUCT(G19:$K$19,G4:$K$4)/SUM(G4:$K$4)) -> 0.26804778 | K24: =IF(SUM(I4:$K$4)=0, "", SUMPRODUCT(I19:$K$19,I4:$K$4)/SUM(I4:$K$4)) -> 0.26741462 | L24: =L19 -> 0.26853936 | M24: =MAX(K24:L24) -> 0.26853936 | N24: =MIN(H24:L24) -> 0.26741462
G25: Price to Earning | H25: =IF(ISERROR(AVERAGEIF(B14:$L14,">0")),"",AVERAGEIF(B14:$L14,">0")) -> 25.103538 | I25: =IF(ISERROR(AVERAGEIF(E14:$L14,">0")),"",AVERAGEIF(E14:$L14,">0")) -> 26.615911 | J25: =IF(ISERROR(AVERAGEIF(G14:$L14,">0")),"",AVERAGEIF(G14:$L14,">0")) -> 25.915206 | K25: =IF(ISERROR(AVERAGEIF(I14:$L14,">0")),"",AVERAGEIF(I14:$L14,">0")) -> 22.988221 | L25: =L14 -> 17.186987 | M25: =MAX(K25:L25) -> 22.988221 | N25: =MIN(H25:L25) -> 17.186987
E49: Date | F49: Open | G49: High | H49: Low | I49: Close | J49: Shares Traded | K49: Turnover (₹ Cr) | L49: Adjest | N49: Date | O49: Open | P49: High | Q49: Low | R49: Close | S49: Prev. Close | T49: Change | U49: % Change
E50: 46234 | F50: 24361.45 | G50: 24429.4 | H50: 24299.7 | I50: 24383.6 | J50: 411693361 | K50: 34459.53 | N50: 45931 | O50: 11.065 | P50: 11.255 | Q50: 10.1525 | R50: 10.29 | S50: 11.065 | T50: -0.78 | U50: -7
E51: 46233 | F51: 24249.55 | G51: 24342.95 | H51: 24187.1 | I51: 24317.15 | J51: 400636260 | K51: 33566.22 | N51: 45933 | O51: 10.2875 | P51: 10.6225 | Q51: 9.945 | R51: 10.06 | S51: 10.2875 | T51: -0.23 | U51: -2.21
E52: 46232 | F52: 24176.65 | G52: 24283.55 | H52: 24136.75 | I52: 24250.2 | J52: 424150311 | K52: 34189.33 | N52: 45936 | O52: 10.06 | P52: 10.5375 | Q52: 9.6575 | R52: 10.19 | S52: 10.06 | T52: 0.13 | U52: 1.29
E53: 46231 | F53: 23971.25 | G53: 24041.15 | H53: 23954.6 | I53: 23985.35 | J53: 437827320 | K53: 35846.87 | N53: 45937 | O53: 10.1925 | P53: 10.45 | Q53: 10 | R53: 10.05 | S53: 10.1925 | T53: -0.14 | U53: -1.4
E54: 46230 | F54: 23928.4 | G54: 24011.6 | H54: 23891.55 | I54: 23995.95 | J54: 319367545 | K54: 25340.46 | N54: 45938 | O54: 10.05 | P54: 10.5225 | Q54: 9.6875 | R54: 10.31 | S54: 10.05 | T54: 0.26 | U54: 2.59
E55: 46227 | F55: 23666.35 | G55: 23823.6 | H55: 23606.3 | I55: 23767.45 | J55: 333870912 | K55: 28825.72 | N55: 45939 | O55: 10.3125 | P55: 10.565 | Q55: 9.9975 | R55: 10.12 | S55: 10.3125 | T55: -0.19 | U55: -1.87
E56: 46226 | F56: 23904.8 | G56: 23990.75 | H56: 23807.2 | I56: 23869.6 | J56: 344042832 | K56: 28259.45 | N56: 45940 | O56: 10.12 | P56: 10.3425 | Q56: 9.71 | R56: 10.1 | S56: 10.12 | T56: -0.02 | U56: -0.2
E57: 46225 | F57: 24150.45 | G57: 24166.3 | H57: 23961.4 | I57: 23996.25 | J57: 304745142 | K57: 25211.83 | N57: 45943 | O57: 10.1025 | P57: 11.2575 | Q57: 9.7775 | R57: 11.01 | S57: 10.1025 | T57: 0.91 | U57: 8.98
E58: 46224 | F58: 24216.05 | G58: 24262.2 | H58: 24135.65 | I58: 24187.7 | J58: 315560285 | K58: 28361.57 | N58: 45944 | O58: 11.0075 | P58: 11.6675 | Q58: 10.0125 | R58: 11.16 | S58: 11.0075 | T58: 0.15 | U58: 1.39
E59: 46223 | F59: 24190.05 | G59: 24266.1 | H59: 24135.85 | I59: 24238.5 | J59: 353095939 | K59: 31370.66 | N59: 45945 | O59: 11.155 | P59: 11.155 | Q59: 10.4325 | R59: 10.53 | S59: 11.155 | T59: -0.63 | U59: -5.6
E60: 46220 | F60: 24127.6 | G60: 24367.3 | H60: 24099.05 | I60: 24334.3 | J60: 387772135 | K60: 28825.71 | N60: 45946 | O60: 10.53 | P60: 11.0575 | Q60: 10.3825 | R60: 10.87 | S60: 10.53 | T60: 0.34 | U60: 3.23
E61: 46219 | F61: 24142.1 | G61: 24186.5 | H61: 24050 | I61: 24072.75 | J61: 264271962 | K61: 24244.17 | N61: 45947 | O61: 10.865 | P61: 11.81 | Q61: 9.775 | R61: 11.63 | S61: 10.865 | T61: 0.77 | U61: 7.04
... E171: 46055 | F171: 24796.5 | G171: 25108.1 | H171: 24679.4 | I171: 25088.4 | J171: 449215604 | K171: 34038.26 | N171: 46111 | O171: 26.8025 | P171: 28.9075 | Q171: 26.8025 | R171: 27.89 | S171: 26.8025 | T171: 1.09 | U171: 4.06
E172: 46054 | F172: 25333.75 | G172: 25440.9 | H172: 24571.75 | I172: 24825.45 | J172: 379370206 | K172: 25572.6
E173: 46052 | F173: 25247.55 | G173: 25370.7 | H173: 25213.65 | I173: 25320.65 | J173: 508388604 | K173: 40772.08
E174: 46051 | F174: 25345 | G174: 25458.15 | H174: 25159.8 | I174: 25418.9 | J174: 582389331 | K174: 44306.95
E175: 46050 | F175: 25258.85 | G175: 25372.1 | H175: 25187.65 | I175: 25342.75 | J175: 574903942 | K175: 42364.52
E176: 46049 | F176: 25063.35 | G176: 25246.65 | H176: 24932.55 | I176: 25175.4 | J176: 618696080 | K176: 50989.25
...

Sheet Quarters
A1: ='Profit & Loss'!A1 -> TATA CONSULTANCY SERVICES LTD | E1: =UPDATE | J1: SCREENER.IN
A3: Narration | B3: ='Data Sheet'!B41 -> 45382 | C3: ='Data Sheet'!C41 -> 45473 | D3: ='Data Sheet'!D41 -> 45565 | E3: ='Data Sheet'!E41 -> 45657 | F3: ='Data Sheet'!F41 -> 45747 | G3: ='Data Sheet'!G41 -> 45838 | H3: ='Data Sheet'!H41 -> 45930 | I3: ='Data Sheet'!I41 -> 46022 | ... K3: ='Data Sheet'!K41 -> 46203
A4: Sales | B4: ='Data Sheet'!B42 -> 61237 | C4: ='Data Sheet'!C42 -> 62613 | D4: ='Data Sheet'!D42 -> 64259 | E4: ='Data Sheet'!E42 -> 63973 | F4: ='Data Sheet'!F42 -> 64479 | G4: ='Data Sheet'!G42 -> 63437 | H4: ='Data Sheet'!H42 -> 65799 | I4: ='Data Sheet'!I42 -> 67087 | ... K4: ='Data Sheet'!K42 -> 72275
A5: Expenses | B5: ='Data Sheet'!B43 -> 44073 | C5: ='Data Sheet'!C43 -> 45951 | D5: ='Data Sheet'!D43 -> 47528 | E5: ='Data Sheet'!E43 -> 46939 | F5: ='Data Sheet'!F43 -> 47499 | G5: ='Data Sheet'!G43 -> 46562 | H5: ='Data Sheet'!H43 -> 47821 | I5: ='Data Sheet'!I43 -> 48818 | ... K5: ='Data Sheet'!K43 -> 53719
A6: Operating Profit | B6: ='Data Sheet'!B50 -> 17164 | C6: ='Data Sheet'!C50 -> 16662 | D6: ='Data Sheet'!D50 -> 16731 | E6: ='Data Sheet'!E50 -> 17034 | F6: ='Data Sheet'!F50 -> 16980 | G6: ='Data Sheet'!G50 -> 16875 | H6: ='Data Sheet'!H50 -> 17978 | I6: ='Data Sheet'!I50 -> 18269 | ... K6: ='Data Sheet'!K50 -> 18556
A7: Other Income | B7: ='Data Sheet'!B44 -> 1157 | C7: ='Data Sheet'!C44 -> 962 | D7: ='Data Sheet'!D44 -> 729 | E7: ='Data Sheet'!E44 -> 1243 | F7: ='Data Sheet'!F44 -> 1028 | G7: ='Data Sheet'!G44 -> 1660 | H7: ='Data Sheet'!H44 -> -268 | I7: ='Data Sheet'!I44 -> -2273 | ... K7: ='Data Sheet'!K44 -> 900
A8: Depreciation | B8: ='Data Sheet'!B45 -> 1246 | C8: ='Data Sheet'!C45 -> 1220 | D8: ='Data Sheet'!D45 -> 1266 | E8: ='Data Sheet'!E45 -> 1377 | F8: ='Data Sheet'!F45 -> 1379 | G8: ='Data Sheet'!G45 -> 1361 | H8: ='Data Sheet'!H45 -> 1413 | I8: ='Data Sheet'!I45 -> 1380 | ... K8: ='Data Sheet'!K45 -> 1239
A9: Interest | B9: ='Data Sheet'!B46 -> 226 | C9: ='Data Sheet'!C46 -> 173 | D9: ='Data Sheet'!D46 -> 162 | E9: ='Data Sheet'!E46 -> 234 | F9: ='Data Sheet'!F46 -> 227 | G9: ='Data Sheet'!G46 -> 195 | H9: ='Data Sheet'!H46 -> 229 | I9: ='Data Sheet'!I46 -> 538 | ... K9: ='Data Sheet'!K46 -> 273
A10: Profit before tax | B10: ='Data Sheet'!B47 -> 16849 | C10: ='Data Sheet'!C47 -> 16231 | D10: ='Data Sheet'!D47 -> 16032 | E10: ='Data Sheet'!E47 -> 16666 | F10: ='Data Sheet'!F47 -> 16402 | G10: ='Data Sheet'!G47 -> 16979 | H10: ='Data Sheet'!H47 -> 16068 | I10: ='Data Sheet'!I47 -> 14078 | ... K10: ='Data Sheet'!K47 -> 17944
A11: Tax | B11: ='Data Sheet'!B48 -> 4347 | C11: ='Data Sheet'!C48 -> 4126 | D11: ='Data Sheet'!D48 -> 4077 | E11: ='Data Sheet'!E48 -> 4222 | F11: ='Data Sheet'!F48 -> 4109 | G11: ='Data Sheet'!G48 -> 4160 | H11: ='Data Sheet'!H48 -> 3937 | I11: ='Data Sheet'!I48 -> 3358 | ... K11: ='Data Sheet'!K48 -> 4524
A12: Net profit | B12: ='Data Sheet'!B49 -> 12434 | C12: ='Data Sheet'!C49 -> 12040 | D12: ='Data Sheet'!D49 -> 11909 | E12: ='Data Sheet'!E49 -> 12380 | F12: ='Data Sheet'!F49 -> 12224 | G12: ='Data Sheet'!G49 -> 12760 | H12: ='Data Sheet'!H49 -> 12075 | I12: ='Data Sheet'!I49 -> 10657 | ... K12: ='Data Sheet'!K49 -> 13349
A14: OPM | B14: =IF(B4>0,B6/B4,"") -> 0.28028806 | C14: =IF(C4>0,C6/C4,"") -> 0.26611087 | D14: =IF(D4>0,D6/D4,"") -> 0.2603682 | E14: =IF(E4>0,E6/E4,"") -> 0.26626858 | F14: =IF(F4>0,F6/F4,"") -> 0.26334155 | G14: =IF(G4>0,G6/G4,"") -> 0.26601195 | H14: =IF(H4>0,H6/H4,"") -> 0.27322604 | I14: =IF(I4>0,I6/I4,"") -> 0.27231803 | ... K14: =IF(K4>0,K6/K4,"") -> 0.25674161

Sheet Balance Sheet
A1: ='Profit & Loss'!A1 -> TATA CONSULTANCY SERVICES LTD | E1: =UPDATE | J1: SCREENER.IN
A3: Narration | B3: ='Data Sheet'!B56 -> 42825 | C3: ='Data Sheet'!C56 -> 43190 | D3: ='Data Sheet'!D56 -> 43555 | E3: ='Data Sheet'!E56 -> 43921 | F3: ='Data Sheet'!F56 -> 44286 | G3: ='Data Sheet'!G56 -> 44651 | H3: ='Data Sheet'!H56 -> 45016 | I3: ='Data Sheet'!I56 -> 45382 | ... K3: ='Data Sheet'!K56 -> 46112
A4: Equity Share Capital | B4: ='Data Sheet'!B57 -> 197 | C4: ='Data Sheet'!C57 -> 191 | D4: ='Data Sheet'!D57 -> 375 | E4: ='Data Sheet'!E57 -> 375 | F4: ='Data Sheet'!F57 -> 370 | G4: ='Data Sheet'!G57 -> 366 | H4: ='Data Sheet'!H57 -> 366 | I4: ='Data Sheet'!I57 -> 362 | ... K4: ='Data Sheet'!K57 -> 362
A5: Reserves | B5: ='Data Sheet'!B58 -> 86017 | C5: ='Data Sheet'!C58 -> 84937 | D5: ='Data Sheet'!D58 -> 89071 | E5: ='Data Sheet'!E58 -> 83751 | F5: ='Data Sheet'!F58 -> 86063 | G5: ='Data Sheet'!G58 -> 88773 | H5: ='Data Sheet'!H58 -> 90058 | I5: ='Data Sheet'!I58 -> 90127 | ... K5: ='Data Sheet'!K58 -> 106878
A6: Borrowings | B6: ='Data Sheet'!B59 -> 289 | C6: ='Data Sheet'!C59 -> 247 | D6: ='Data Sheet'!D59 -> 62 | E6: ='Data Sheet'!E59 -> 8174 | F6: ='Data Sheet'!F59 -> 7795 | G6: ='Data Sheet'!G59 -> 7818 | H6: ='Data Sheet'!H59 -> 7688 | I6: ='Data Sheet'!I59 -> 8021 | ... K6: ='Data Sheet'!K59 -> 11283
A7: Other Liabilities | B7: ='Data Sheet'!B60 -> 15830 | C7: ='Data Sheet'!C60 -> 19751 | D7: ='Data Sheet'!D60 -> 24393 | E7: ='Data Sheet'!E60 -> 27827 | F7: ='Data Sheet'!F60 -> 35764 | G7: ='Data Sheet'!G60 -> 43967 | H7: ='Data Sheet'!H60 -> 44747 | I7: ='Data Sheet'!I60 -> 46962 | ... K7: ='Data Sheet'!K60 -> 62644
A8: Total | B8: ='Data Sheet'!B61 -> 102333 | C8: ='Data Sheet'!C61 -> 105126 | D8: ='Data Sheet'!D61 -> 113901 | E8: ='Data Sheet'!E61 -> 120127 | F8: ='Data Sheet'!F61 -> 129992 | G8: ='Data Sheet'!G61 -> 140924 | H8: ='Data Sheet'!H61 -> 142859 | I8: ='Data Sheet'!I61 -> 145472 | ... K8: ='Data Sheet'!K61 -> 181167
A10: Net Block | B10: ='Data Sheet'!B62 -> 11701 | C10: ='Data Sheet'!C62 -> 11973 | D10: ='Data Sheet'!D62 -> 12290 | E10: ='Data Sheet'!E62 -> 20928 | F10: ='Data Sheet'!F62 -> 21021 | G10: ='Data Sheet'!G62 -> 21298 | H10: ='Data Sheet'!H62 -> 20515 | I10: ='Data Sheet'!I62 -> 19604 | ... K10: ='Data Sheet'!K62 -> 31343
A11: Capital Work in Progress | B11: ='Data Sheet'!B63 -> 1541 | C11: ='Data Sheet'!C63 -> 1278 | D11: ='Data Sheet'!D63 -> 963 | E11: ='Data Sheet'!E63 -> 906 | F11: ='Data Sheet'!F63 -> 926 | G11: ='Data Sheet'!G63 -> 1205 | H11: ='Data Sheet'!H63 -> 1234 | I11: ='Data Sheet'!I63 -> 1564 | ... K11: ='Data Sheet'!K63 -> 2665
A12: Investments | B12: ='Data Sheet'!B64 -> 41980 | C12: ='Data Sheet'!C64 -> 36008 | D12: ='Data Sheet'!D64 -> 29330 | E12: ='Data Sheet'!E64 -> 26356 | F12: ='Data Sheet'!F64 -> 29373 | G12: ='Data Sheet'!G64 -> 30485 | H12: ='Data Sheet'!H64 -> 37163 | I12: ='Data Sheet'!I64 -> 31762 | ... K12: ='Data Sheet'!K64 -> 33988
A13: Other Assets | B13: ='Data Sheet'!B65 -> 47111 | C13: ='Data Sheet'!C65 -> 55867 | D13: ='Data Sheet'!D65 -> 71318 | E13: ='Data Sheet'!E65 -> 71937 | F13: ='Data Sheet'!F65 -> 78672 | G13: ='Data Sheet'!G65 -> 87936 | H13: ='Data Sheet'!H65 -> 83947 | I13: ='Data Sheet'!I65 -> 92542 | ... K13: ='Data Sheet'!K65 -> 113171
A14: Total | B14: ='Data Sheet'!B66 -> 102333 | C14: ='Data Sheet'!C66 -> 105126 | D14: ='Data Sheet'!D66 -> 113901 | E14: ='Data Sheet'!E66 -> 120127 | F14: ='Data Sheet'!F66 -> 129992 | G14: ='Data Sheet'!G66 -> 140924 | H14: ='Data Sheet'!H66 -> 142859 | I14: ='Data Sheet'!I66 -> 145472 | ... K14: ='Data Sheet'!K66 -> 181167
A16: Working Capital | B16: =B13-B7 -> 31281 | C16: =C13-C7 -> 36116 | D16: =D13-D7 -> 46925 | E16: =E13-E7 -> 44110 | F16: =F13-F7 -> 42908 | G16: =G13-G7 -> 43969 | H16: =H13-H7 -> 39200 | I16: =I13-I7 -> 45580 | ... K16: =K13-K7 -> 50527
A17: Debtors | B17: ='Data Sheet'!B67 -> 22617 | C17: ='Data Sheet'!C67 -> 24943 | D17: ='Data Sheet'!D67 -> 27346 | E17: ='Data Sheet'!E67 -> 30532 | F17: ='Data Sheet'!F67 -> 30079 | G17: ='Data Sheet'!G67 -> 41810 | H17: ='Data Sheet'!H67 -> 49954 | I17: ='Data Sheet'!I67 -> 53577 | ... K17: ='Data Sheet'!K67 -> 67714
A18: Inventory | B18: ='Data Sheet'!B68 -> 21 | C18: ='Data Sheet'!C68 -> 26 | D18: ='Data Sheet'!D68 -> 10 | E18: ='Data Sheet'!E68 -> 5 | F18: ='Data Sheet'!F68 -> 8 | G18: ='Data Sheet'!G68 -> 20 | H18: ='Data Sheet'!H68 -> 28 | I18: ='Data Sheet'!I68 -> 28 | ... K18: ='Data Sheet'!K68 -> 29
A20: Debtor Days | B20: =IF('Profit & Loss'!B4>0,'Balance Sheet'!B17/('Profit & Loss'!B4/365),0) -> 69.979528 | C20: =IF('Profit & Loss'!C4>0,'Balance Sheet'!C17/('Profit & Loss'!C4/365),0) -> 73.955314 | D20: =IF('Profit & Loss'!D4>0,'Balance Sheet'!D17/('Profit & Loss'!D4/365),0) -> 68.148884 | E20: =IF('Profit & Loss'!E4>0,'Balance Sheet'!E17/('Profit & Loss'!E4/365),0) -> 71.005104 | F20: =IF('Profit & Loss'!F4>0,'Balance Sheet'!F17/('Profit & Loss'!F4/365),0) -> 66.871943 | G20: =IF('Profit & Loss'!G4>0,'Balance Sheet'!G17/('Profit & Loss'!G4/365),0) -> 79.58452 | H20: =IF('Profit & Loss'!H4>0,'Balance Sheet'!H17/('Profit & Loss'!H4/365),0) -> 80.87187 | I20: =IF('Profit & Loss'!I4>0,'Balance Sheet'!I17/('Profit & Loss'!I4/365),0) -> 81.179632 | ... K20: =IF('Profit & Loss'!K4>0,'Balance Sheet'!K17/('Profit & Loss'!K4/365),0) -> 92.560548
A21: Inventory Turnover | B21: =IF('Balance Sheet'!B18>0,'Profit & Loss'!B4/'Balance Sheet'!B18,0) -> 5617.4286 | C21: =IF('Balance Sheet'!C18>0,'Profit & Loss'!C4/'Balance Sheet'!C18,0) -> 4734.7692 | D21: =IF('Balance Sheet'!D18>0,'Profit & Loss'!D4/'Balance Sheet'!D18,0) -> 14646.3 | E21: =IF('Balance Sheet'!E18>0,'Profit & Loss'!E4/'Balance Sheet'!E18,0) -> 31389.8 | F21: =IF('Balance Sheet'!F18>0,'Profit & Loss'!F4/'Balance Sheet'!F18,0) -> 20522.125 | G21: =IF('Balance Sheet'!G18>0,'Profit & Loss'!G4/'Balance Sheet'!G18,0) -> 9587.7 | H21: =IF('Balance Sheet'!H18>0,'Profit & Loss'!H4/'Balance Sheet'!H18,0) -> 8052.0714 | I21: =IF('Balance Sheet'!I18>0,'Profit & Loss'!I4/'Balance Sheet'!I18,0) -> 8603.3214 | ... K21: =IF('Balance Sheet'!K18>0,'Profit & Loss'!K4/'Balance Sheet'!K18,0) -> 9207.6207
A23: Return on Equity | B23: =IF(SUM('Balance Sheet'!B4:B5)>0,'Profit & Loss'!B12/SUM('Balance Sheet'!B4:B5),"") -> 0.30492727 | C23: =IF(SUM('Balance Sheet'!C4:C5)>0,'Profit & Loss'!C12/SUM('Balance Sheet'!C4:C5),"") -> 0.30337844 | D23: =IF(SUM('Balance Sheet'!D4:D5)>0,'Profit & Loss'!D12/SUM('Balance Sheet'!D4:D5),"") -> 0.35185475 | E23: =IF(SUM('Balance Sheet'!E4:E5)>0,'Profit & Loss'!E12/SUM('Balance Sheet'!E4:E5),"") -> 0.38442336 | F23: =IF(SUM('Balance Sheet'!F4:F5)>0,'Profit & Loss'!F12/SUM('Balance Sheet'!F4:F5),"") -> 0.37520392 | G23: =IF(SUM('Balance Sheet'!G4:G5)>0,'Profit & Loss'!G12/SUM('Balance Sheet'!G4:G5),"") -> 0.42996892 | H23: =IF(SUM('Balance Sheet'!H4:H5)>0,'Profit & Loss'!H12/SUM('Balance Sheet'!H4:H5),"") -> 0.46610413 | I23: =IF(SUM('Balance Sheet'!I4:I5)>0,'Profit & Loss'!I12/SUM('Balance Sheet'!I4:I5),"") -> 0.50733238 | ... K23: =IF(SUM('Balance Sheet'!K4:K5)>0,'Profit & Loss'!K12/SUM('Balance Sheet'!K4:K5),"") -> 0.45887728
A24: Return on Capital Emp | C24: =IF((B4+B5+B6+C4+C5+C6)>0,('Profit & Loss'!C10+'Profit & Loss'!C9)*2/(B4+B5+B6+C4+C5+C6),"") -> 0.39730507 | D24: =IF((C4+C5+C6+D4+D5+D6)>0,('Profit & Loss'!D10+'Profit & Loss'!D9)*2/(C4+C5+C6+D4+D5+D6),"") -> 0.47758787 | E24: =IF((D4+D5+D6+E4+E5+E6)>0,('Profit & Loss'!E10+'Profit & Loss'!E9)*2/(D4+D5+D6+E4+E5+E6),"") -> 0.4749186 | F24: =IF((E4+E5+E6+F4+F5+F6)>0,('Profit & Loss'!F10+'Profit & Loss'!F9)*2/(E4+E5+E6+F4+F5+F6),"") -> 0.47603577 | G24: =IF((F4+F5+F6+G4+G5+G6)>0,('Profit & Loss'!G10+'Profit & Loss'!G9)*2/(F4+F5+F6+G4+G5+G6),"") -> 0.5489029 | H24: =IF((G4+G5+G6+H4+H5+H6)>0,('Profit & Loss'!H10+'Profit & Loss'!H9)*2/(G4+G5+G6+H4+H5+H6),"") -> 0.591442 | I24: =IF((H4+H5+H6+I4+I5+I6)>0,('Profit & Loss'!I10+'Profit & Loss'!I9)*2/(H4+H5+H6+I4+I5+I6),"") -> 0.63853485 | J24: =IF((I4+I5+I6+J4+J5+J6)>0,('Profit & Loss'!J10+'Profit & Loss'!J9)*2/(I4+I5+I6+J4+J5+J6),"") -> 0.65259699 | K24: =IF((J4+J5+J6+K4+K5+K6)>0,('Profit & Loss'!K10+'Profit & Loss'!K9)*2/(J4+J5+J6+K4+K5+K6),"") -> 0.59921588

Sheet Cash Flow
A1: ='Balance Sheet'!A1 -> TATA CONSULTANCY SERVICES LTD | E1: =UPDATE | J1: SCREENER.IN
A3: Narration | B3: ='Data Sheet'!B81 -> 42825 | C3: ='Data Sheet'!C81 -> 43190 | D3: ='Data Sheet'!D81 -> 43555 | E3: ='Data Sheet'!E81 -> 43921 | F3: ='Data Sheet'!F81 -> 44286 | G3: ='Data Sheet'!G81 -> 44651 | H3: ='Data Sheet'!H81 -> 45016 | I3: ='Data Sheet'!I81 -> 45382 | ... K3: ='Data Sheet'!K81 -> 46112
A4: Cash from Operating Activity | B4: ='Data Sheet'!B82 -> 25223 | C4: ='Data Sheet'!C82 -> 25067 | D4: ='Data Sheet'!D82 -> 28593 | E4: ='Data Sheet'!E82 -> 32369 | F4: ='Data Sheet'!F82 -> 38802 | G4: ='Data Sheet'!G82 -> 39949 | H4: ='Data Sheet'!H82 -> 41965 | I4: ='Data Sheet'!I82 -> 44338 | ... K4: ='Data Sheet'!K82 -> 52094
A5: Cash from Investing Activity | B5: ='Data Sheet'!B83 -> -16895 | C5: ='Data Sheet'!C83 -> 3104 | D5: ='Data Sheet'!D83 -> 1645 | E5: ='Data Sheet'!E83 -> 8968 | F5: ='Data Sheet'!F83 -> -7956 | G5: ='Data Sheet'!G83 -> -738 | H5: ='Data Sheet'!H83 -> 548 | I5: ='Data Sheet'!I83 -> 6091 | ... K5: ='Data Sheet'!K83 -> -11886
A6: Cash from Financing Activity | B6: ='Data Sheet'!B84 -> -11026 | C6: ='Data Sheet'!C84 -> -26885 | D6: ='Data Sheet'!D84 -> -27897 | E6: ='Data Sheet'!E84 -> -39915 | F6: ='Data Sheet'!F84 -> -32634 | G6: ='Data Sheet'!G84 -> -33581 | H6: ='Data Sheet'!H84 -> -47878 | I6: ='Data Sheet'!I84 -> -48536 | ... K6: ='Data Sheet'!K84 -> -42133
A7: Net Cash Flow | B7: ='Data Sheet'!B85 -> -2698 | C7: ='Data Sheet'!C85 -> 1286 | D7: ='Data Sheet'!D85 -> 2341 | E7: ='Data Sheet'!E85 -> 1422 | F7: ='Data Sheet'!F85 -> -1788 | G7: ='Data Sheet'!G85 -> 5630 | H7: ='Data Sheet'!H85 -> -5365 | I7: ='Data Sheet'!I85 -> 1893 | ... K7: ='Data Sheet'!K85 -> -1925
A9: Fixed assets purchased | B9: -2949 | C9: -1987 | D9: -1989 | E9: -1862 | F9: -2231 | G9: -3249 | H9: -3176 | I9: -2995 | J9: -3100 | K9: -2674 | L9: -3937 | M9: -4146
A10: Fixed assets sold | B10: 7 | C10: 22 | D10: 36 | E10: 58 | F10: 99 | G10: 161 | H10: 37 | I10: 31 | J10: 37 | K10: 24 | L10: 23 | M10: 65
A11: Investments purchased | B11: -67371 | C11: -116847 | D11: -121423 | E11: -97473 | F11: -96751 | G11: -80002 | H11: -54462 | I11: -75374 | J11: -129745 | K11: -141011 | L11: -145962 | M11: -152114
A12: Investments sold | B12: 69361 | C12: 97154 | D12: 102798 | E12: 103482 | F12: 104133 | G12: 84089 | H12: 51630 | I12: 73852 | J12: 122687 | K12: 147204 | L12: 147695 | M12: 148023
A23: Particulars | B23: Value
A24: Current Market Price | B24: 2365.6
A25: Intrinsic Value (DCF) | B25: 2766.23
A26: Potential Upside | B26: 0.1694
A27: DCF Valuation | B27: Undervalued
A28: Recommendation | B28: BUY

Sheet Customization
A1: How to use it?
A3: You can customize this workbook as you want.
B4: You can add custom formating, add conditional formating, add your own formulas… do ANYTHING.
B5: Please don't edit the "Data Sheet" only.
A7: After customization, you can upload this back on Screener.
B8: Upload on: | C8: https://www.screener.in/excel/
A10: Download your customized workbooks now onwards.
B11: Now whenever you will "Export to excel" from Screener, it will export your customized file.
A14: TESTING:
B15: This is a testing feature currently.
B16: You can report any formula errors on the worksheet at: support@screener.in

Sheet Data Sheet
A1: COMPANY NAME | B1: TATA CONSULTANCY SERVICES LTD | E1: =IF(B2<>B3, "A NEW VERSION OF THE WORKSHEET IS AVAILABLE", "")
A2: LATEST VERSION | B2: 2.1 | E2: PLEASE DO NOT MAKE ANY CHANGES TO THIS SHEET
A3: CURRENT VERSION | B3: 2.1
A5: META
A6: Number of shares | B6: =IF(B9>0, B9/B8, 0) -> 361.80875
A7: Face Value | B7: 1
A8: Current Price | B8: 2365.6
A9: Market Capitalization | B9: 855894.78
A15: PROFIT & LOSS
A16: Report Date | B16: 42825 | C16: 43190 | D16: 43555 | E16: 43921 | F16: 44286 | G16: 44651 | H16: 45016 | I16: 45382 | J16: 45747 | K16: 46112
A17: Sales | B17: 117966 | C17: 123104 | D17: 146463 | E17: 156949 | F17: 164177 | G17: 191754 | H17: 225458 | I17: 240893 | J17: 255324 | K17: 267021
A18: Raw Material Cost | B18: 94 | C18: 86 | D18: 40 | E18: 18 | F18: 14 | G18: 29 | H18: 37 | I18: 42 | J18: 49 | K18: 43
A19: Change in Inventory | B19: 1
A20: Power and Fuel
A21: Other Mfr. Exp | B21: 2715 | C21: 2614 | D21: 2230 | E21: 1887 | F21: 1448 | G21: 1134 | H21: 1844 | I21: 3660 | J21: 11599 | K21: 4356
A22: Employee Cost | B22: 61621 | C22: 66396 | D22: 78246 | E22: 85952 | F22: 91814 | G22: 107554 | H22: 127522 | I22: 140131 | J22: 145788 | K22: 154994
A23: Selling and admin | B23: 16392 | C23: 16808 | D23: 20387 | E23: 20527 | F23: 18322 | G23: 23187 | H23: 28913 | I23: 24151 | J23: 20729 | K23: 24434
A24: Other Expenses | B24: 4834 | C24: 4684 | D24: 6054 | E24: 6456 | F24: 6033 | G24: 6793 | H24: 7883 | I24: 8613 | J24: 9752 | K24: 10796
A25: Other Income | B25: 4221 | C25: 3642 | D25: 4311 | E25: 4592 | F25: 1916 | G25: 4018 | H25: 3449 | I25: 3464 | J25: 3962 | K25: -124
A26: Depreciation | B26: 1987 | C26: 2014 | D26: 2056 | E26: 3529 | F26: 4065 | G26: 4604 | H26: 5022 | I26: 4985 | J26: 5242 | K26: 5560
A27: Interest | B27: 32 | C27: 52 | D27: 198 | E27: 924 | F27: 637 | G27: 784 | H27: 779 | I27: 778 | J27: 796 | K27: 1227
A28: Profit before tax | B28: 34513 | C28: 34092 | D28: 41563 | E28: 42248 | F28: 43760 | G28: 51687 | H28: 56907 | I28: 61997 | J28: 65331 | K28: 65487
A29: Tax | B29: 8156 | C29: 8212 | D29: 10001 | E29: 9801 | F29: 11198 | G29: 13238 | H29: 14604 | I29: 15898 | J29: 16534 | K29: 16033
A30: Net profit | B30: 26289 | C30: 25826 | D30: 31472 | E30: 32340 | F30: 32430 | G30: 38327 | H30: 42147 | I30: 45908 | J30: 48553 | K30: 49210
A31: Dividend Amount | B31: 9259 | C31: 9550 | D31: 11250 | E31: 27375 | F31: 14060 | G31: 15738 | H31: 42090 | I31: 26426 | J31: 45612 | K31: 39820
A40: Quarters
A41: Report Date | B41: 45382 | C41: 45473 | D41: 45565 | E41: 45657 | F41: 45747 | G41: 45838 | H41: 45930 | I41: 46022 | J41: 46112 | K41: 46203
A42: Sales | B42: 61237 | C42: 62613 | D42: 64259 | E42: 63973 | F42: 64479 | G42: 63437 | H42: 65799 | I42: 67087 | J42: 70698 | K42: 72275
A43: Expenses | B43: 44073 | C43: 45951 | D43: 47528 | E43: 46939 | F43: 47499 | G43: 46562 | H43: 47821 | I43: 48818 | J43: 51422 | K43: 53719
A44: Other Income | B44: 1157 | C44: 962 | D44: 729 | E44: 1243 | F44: 1028 | G44: 1660 | H44: -268 | I44: -2273 | J44: 757 | K44: 900
A45: Depreciation | B45: 1246 | C45: 1220 | D45: 1266 | E45: 1377 | F45: 1379 | G45: 1361 | H45: 1413 | I45: 1380 | J45: 1406 | K45: 1239
A46: Interest | B46: 226 | C46: 173 | D46: 162 | E46: 234 | F46: 227 | G46: 195 | H46: 229 | I46: 538 | J46: 265 | K46: 273
A47: Profit before tax | B47: 16849 | C47: 16231 | D47: 16032 | E47: 16666 | F47: 16402 | G47: 16979 | H47: 16068 | I47: 14078 | J47: 18362 | K47: 17944
A48: Tax | B48: 4347 | C48: 4126 | D48: 4077 | E48: 4222 | F48: 4109 | G48: 4160 | H48: 3937 | I48: 3358 | J48: 4578 | K48: 4524
A49: Net profit | B49: 12434 | C49: 12040 | D49: 11909 | E49: 12380 | F49: 12224 | G49: 12760 | H49: 12075 | I49: 10657 | J49: 13718 | K49: 13349
A50: Operating Profit | B50: 17164 | C50: 16662 | D50: 16731 | E50: 17034 | F50: 16980 | G50: 16875 | H50: 17978 | I50: 18269 | J50: 19276 | K50: 18556
A55: BALANCE SHEET
A56: Report Date | B56: 42825 | C56: 43190 | D56: 43555 | E56: 43921 | F56: 44286 | G56: 44651 | H56: 45016 | I56: 45382 | J56: 45747 | K56: 46112
A57: Equity Share Capital | B57: 197 | C57: 191 | D57: 375 | E57: 375 | F57: 370 | G57: 366 | H57: 366 | I57: 362 | J57: 362 | K57: 362
A58: Reserves | B58: 86017 | C58: 84937 | D58: 89071 | E58: 83751 | F58: 86063 | G58: 88773 | H58: 90058 | I58: 90127 | J58: 94394 | K58: 106878
...

Sheet One Page Profil
B2: Tcs-One Page Profile
B11: Key Financial Matrics | D11: ='Historicail Financial Statement'!H4 -> 45016 | E11: ='Historicail Financial Statement'!I4 -> 45382 | F11: ='Historicail Financial Statement'!J4 -> 45747 | G11: ='Historicail Financial Statement'!K4 -> 46112 | I11: 5yers - Shre Price
B13: Total Sales | D13: ='Historicail Financial Statement'!H7 -> 225458 | E13: ='Historicail Financial Statement'!I7 -> 240893 | F13: ='Historicail Financial Statement'!J7 -> 255324 | G13: ='Historicail Financial Statement'!K7 -> 267021
B14: Sales Growth (y-oy) | D14: ='Historicail Financial Statement'!H8 -> 0.17576687 | E14: ='Historicail Financial Statement'!I8 -> 0.068460645 | F14: ='Historicail Financial Statement'!J8 -> 0.059906265 | G14: ='Historicail Financial Statement'!K8 -> 0.04581238
B15: Gross Profit Margin (%) | D15: ='Historicail Financial Statement'!G13 -> 0.99393494 | E15: ='Historicail Financial Statement'!H13 -> 0.99165698 | F15: ='Historicail Financial Statement'!I13 -> 0.98463218 | G15: ='Historicail Financial Statement'!J13 -> 0.95437953
B16: EBITDA Margin (%) | D16: ='Historicail Financial Statement'!H18 -> 0.26283831 | E16: ='Historicail Financial Statement'!I18 -> 0.26690688 | F16: ='Historicail Financial Statement'!J18 -> 0.26400573 | G16: ='Historicail Financial Statement'!K18 -> 0.27113223
B17: EBIT Margin (%) | D17: ='Historicail Financial Statement'!H24 -> 0.24056365 | E17: ='Historicail Financial Statement'!I24 -> 0.24621305 | F17: ='Historicail Financial Statement'!J24 -> 0.24347496 | G17: ='Historicail Financial Statement'!K24 -> 0.2503099
B18: Net Profit Margin(%) | D18: ='Historicail Financial Statement'!H39 -> 0.1876314 | E18: ='Historicail Financial Statement'!I39 -> 0.19136712 | F18: ='Historicail Financial Statement'!J39 -> 0.19111795 | G18: ='Historicail Financial Statement'!K39 -> 0.18520641
B19: Earning Per Share in (Cr.rs) | D19: ='Historicail Financial Statement'!H43 -> 115.6104 | E19: ='Historicail Financial Statement'!I43 -> 127.41218 | F19: ='Historicail Financial Statement'!J43 -> 134.86913 | G19: ='Historicail Financial Statement'!K43 -> 136.685
B20: EPS Growth (y-oy) | D20: ='Historicail Financial Statement'!H44 -> 0.10023668 | E20: ='Historicail Financial Statement'!I44 -> 0.10208236 | F20: ='Historicail Financial Statement'!J44 -> 0.058526215 | G20: ='Historicail Financial Statement'!K44 -> 0.013463942
B21: Divident Per Share | D21: ='Historicail Financial Statement'!H47 -> 0.9949649 | E21: ='Historicail Financial Statement'!I47 -> 0.57324454 | F21: ='Historicail Financial Statement'!J47 -> 0.93472959 | G21: ='Historicail Financial Statement'!K47 -> 0.8051927
B22: DPS Growth (y-oy) | D22: ='Data Sheet'!H88 -> 0.19478594 | E22: ='Data Sheet'!I88 -> 0.072526725 | F22: ='Data Sheet'!J88 -> 0.10207738 | G22: ='Data Sheet'!K88 -> 0.1468008
B24: Key Financial ratios | D24: =D11 -> 45016 | E24: =E11 -> 45382 | F24: =F11 -> 45747 | G24: =G11 -> 46112 | I24: Valume
B26: Price to Earning | D26: ='Data Sheet'!$B$8/'Historicail Financial Statement'!H43 -> 20.461828 | E26: ='Data Sheet'!$B$8/'Historicail Financial Statement'!I43 -> 18.566514 | F26: ='Data Sheet'!$B$8/'Historicail Financial Statement'!J43 -> 17.539966 | G26: ='Data Sheet'!$B$8/'Historicail Financial Statement'!K43 -> 17.306947
B27: EV/EBITDA | D27: ='Data Sheet'!H105/'Historicail Financial Statement'!H17 -> 1.9231092 | E27: ='Data Sheet'!I105/'Historicail Financial Statement'!I17 -> 2.0993985 | F27: ='Data Sheet'!J105/'Historicail Financial Statement'!J17 -> 1.8455452 | G27: ='Data Sheet'!K105/'Historicail Financial Statement'!K17 -> 1.1564141
B28: EV/Sales | D28: ='Data Sheet'!H105/'Historicail Financial Statement'!H7 -> 0.50546677 | E28: ='Data Sheet'!I105/'Historicail Financial Statement'!I7 -> 0.56034391 | F28: ='Data Sheet'!J105/'Historicail Financial Statement'!J7 -> 0.48723451 | G28: ='Data Sheet'!K105/'Historicail Financial Statement'!K7 -> 0.31354113
B29: Price to Book Valu | D29: ='Data Sheet'!H108 -> 1.2972831 | E29: ='Data Sheet'!I108 -> 1.5498892 | F29: ='Data Sheet'!J108 -> 1.3769436 | G29: ='Data Sheet'!K108 -> 0.79585105
B30: Return on Equity | D30: ='Data Sheet'!H109 -> 0.13353756 | E30: ='Data Sheet'!I109 -> 0.11777122 | F30: ='Data Sheet'!J109 -> 0.14477184 | G30: ='Data Sheet'!K109 -> 0.12447781
B31: Return on CapitalEmployed | D31: ='Data Sheet'!H110 -> 0.68704134 | E31: ='Data Sheet'!I110 -> 0.73493046 | F31: ='Data Sheet'!J110 -> 0.71128586 | G31: ='Data Sheet'!K110 -> 0.61083503
B34: Top 10 Share Holder | D34: Share Pres | E34: Shares Holding | G34: Current Mareket valu | I34: Share Holing Pettren
B35: Tata Sons Private Limited | D35: 0.7174 | E35: 2595499419 | G35: =E35*Comps_val!$P$28/100000000 -> 61399.134
B36: LIC | D36: 0.0552 | E36: 199553451 | G36: =E36*Comps_val!$P$28/100000000 -> 4720.6364
B37: SBI Mutual Fund | D37: 0.0125 | E37: 45239395 | G37: =E37*Comps_val!$P$28/100000000 -> 1070.1831
B38: ICICI Prudential Mutual | D38: 0.0106 | E38: 38172688 | G38: =E38*Comps_val!$P$28/100000000 -> 903.01311
B39: National Pension | D39: 0.0079 | E39: 28525843 | G39: =E39*Comps_val!$P$28/100000000 -> 674.80734
B40: Nippon Life India | D40: 0.005 | E40: 17924007 | G40: =E40*Comps_val!$P$28/100000000 -> 424.01031
B41: UTI Mutual Fund | D41: 0.0049 | E41: 17573906 | G41: =E41*Comps_val!$P$28/100000000 -> 415.72832
B42: HDFC Mutual Fund | D42: 0.0046 | E42: 16686284 | G42: =E42*Comps_val!$P$28/100000000 -> 394.73073
B43: VTI | D43: 0.0041 | E43: 14892949 | G43: =E43*Comps_val!$P$28/100000000 -> 352.3076
B44: V ME | D44: 0.0039 | E44: 14139580 | G44: =E44*Comps_val!$P$28/100000000 -> 334.4859
B45: Managireal Ramunuration | D45: Disgnation | E45: Remuniration (INR.Crs) | G45: Salary Per Month | I45: Capital Sturcture
B46: K. Krithivasan | D46: CEO | E46: 26.52 | G46: 221
B47: Samir Seksaria | D47: CFO | E47: 8.64 | G47: 72 | I47: Share Price on | L47: ='Data Sheet'!B8 -> 2365.6
B48: Milind Lakkad | D48: CHRO | E48: 6.18 | G48: 51.5 | I48: No of Shares | L48: ='Data Sheet'!B6 -> 361.80875
B49: Ashok Pai | D49: Head – Global Consulting | E49: 5.14 | G49: 4.5 | I49: MCP | L49: =L47*L48 -> 855894.78
B50: Siva Ganesan | D50: Head – AI & Data Business Unit | E50: 5.12 | G50: 4.2 | I50: Less: Cash | L50: ='Data Sheet'!K69 -> 12908
B51: V. Rajanna | D51: President – Technology | E51: 6.15. | G51: 5.2 | I51: Add : Total Debt | L51: ='Data Sheet'!K102 -> 11283
B52: Krishnan Ramanujam | D52: President -CBG | E52: 4.15 | G52: 3.5 | I52: Add:monatary Intrast | L52: ='Data Sheet'!K46 -> 273
I53: Enteprise Value | L53: =L49+L51+L52-(L50) -> 854542.78
B54: Recent Update

Sheet Historicail Financial Statement
B3: ="Historical Financial Statement - "&'Data Sheet'!B1 -> Historical Financial Statement - TATA CONSULTANCY SERVICES LTD
B4: Years | D4: ='Data Sheet'!D16 -> 43555 | E4: ='Data Sheet'!E16 -> 43921 | F4: ='Data Sheet'!F16 -> 44286 | G4: ='Data Sheet'!G16 -> 44651 | H4: ='Data Sheet'!H16 -> 45016 | I4: ='Data Sheet'!I16 -> 45382 | J4: ='Data Sheet'!J16 -> 45747 | K4: ='Data Sheet'!K16 -> 46112 | L4: LTM
A6: # | B6: ="Income Statement - "&'Data Sheet'!B1 -> Income Statement - TATA CONSULTANCY SERVICES LTD
B7: Sales | D7: =IFERROR('Data Sheet'!D17,0) -> 146463 | E7: =IFERROR('Data Sheet'!E17,0) -> 156949 | F7: =IFERROR('Data Sheet'!F17,0) -> 164177 | G7: =IFERROR('Data Sheet'!G17,0) -> 191754 | H7: =IFERROR('Data Sheet'!H17,0) -> 225458 | I7: =IFERROR('Data Sheet'!I17,0) -> 240893 | J7: =IFERROR('Data Sheet'!J17,0) -> 255324 | K7: =IFERROR('Data Sheet'!K17,0) -> 267021 | L7: =IFERROR(SUM('Data Sheet'!H42:K42),0) -> 275859
B8: Sales Growth | D8: - | E8: =E7/D7-1 -> 0.071594874 | F8: =F7/E7-1 -> 0.046053177 | G8: =G7/F7-1 -> 0.16797115 | H8: =H7/G7-1 -> 0.17576687 | I8: =I7/H7-1 -> 0.068460645 | J8: =J7/I7-1 -> 0.059906265 | K8: =K7/J7-1 -> 0.04581238 | L8: =L7/K7-1 -> 0.03309852
B10: COGS | D10: =IFERROR(SUM('Data Sheet'!D18:D21),0) -> 2270 | E10: =IFERROR(SUM('Data Sheet'!E18:E21),0) -> 1905 | F10: =IFERROR(SUM('Data Sheet'!F18:F21),0) -> 1462 | G10: =IFERROR(SUM('Data Sheet'!G18:G21),0) -> 1163 | H10: =IFERROR(SUM('Data Sheet'!H18:H21),0) -> 1881 | I10: =IFERROR(SUM('Data Sheet'!I18:I21),0) -> 3702 | J10: =IFERROR(SUM('Data Sheet'!J18:J21),0) -> 11648 | K10: =IFERROR(SUM('Data Sheet'!K18:K21),0) -> 4399 | L10: =IFERROR(SUM('Data Sheet'!H43:K43),0) -> 201780
B11: COGS % Sales | D11: =D10/D7 -> 0.015498795 | E11: =E10/E7 -> 0.012137701 | F11: =F10/F7 -> 0.0089050232 | G11: =G10/G7 -> 0.0060650625 | H11: =H10/H7 -> 0.0083430173 | I11: =I10/I7 -> 0.015367819 | J11: =J10/J7 -> 0.045620467 | K11: =K10/K7 -> 0.01647436 | L11: =L10/L7 -> 0.73146064
B12: Gross Profit | D12: =D7-D10 -> 144193 | E12: =E7-E10 -> 155044 | F12: =F7-F10 -> 162715 | G12: =G7-G10 -> 190591 | H12: =H7-H10 -> 223577 | I12: =I7-I10 -> 237191 | J12: =J7-J10 -> 243676 | K12: =K7-K10 -> 262622 | L12: =L7-L10 -> 74079
B13: Gross Margins | D13: =D12/D7 -> 0.98450121 | E13: =E12/E7 -> 0.9878623 | F13: =F12/F7 -> 0.99109498 | G13: =G12/G7 -> 0.99393494 | H13: =H12/H7 -> 0.99165698 | I13: =I12/I7 -> 0.98463218 | J13: =J12/J7 -> 0.95437953 | K13: =K12/K7 -> 0.98352564 | L13: =L12/L7 -> 0.26853936
B15: Seling & Genral Expances | D15: =IFERROR(SUM('Data Sheet'!D22:D24),0) -> 104687 | E15: =IFERROR(SUM('Data Sheet'!E22:E24),0) -> 112935 | F15: =IFERROR(SUM('Data Sheet'!F22:F24),0) -> 116169 | G15: =IFERROR(SUM('Data Sheet'!G22:G24),0) -> 137534 | H15: =IFERROR(SUM('Data Sheet'!H22:H24),0) -> 164318 | I15: =IFERROR(SUM('Data Sheet'!I22:I24),0) -> 172895 | J15: =IFERROR(SUM('Data Sheet'!J22:J24),0) -> 176269 | K15: =IFERROR(SUM('Data Sheet'!K22:K24),0) -> 190224
B16: S&Gexp % Sales | D16: =D15/D7 -> 0.71476755 | E16: =E15/E7 -> 0.71956495 | F16: =F15/F7 -> 0.70758389 | G16: =G15/G7 -> 0.71724188 | H16: =H15/H7 -> 0.72881867 | I16: =I15/I7 -> 0.7177253 | J16: =J15/J7 -> 0.6903738 | K16: =K15/K7 -> 0.71239341 | L16: =L15/L7 -> 0
B17: EBITDA | D17: =D12-D15 -> 39506 | E17: =E12-E15 -> 42109 | F17: =F12-F15 -> 46546 | G17: =G12-G15 -> 53057 | H17: =H12-H15 -> 59259 | I17: =I12-I15 -> 64296 | J17: =J12-J15 -> 67407 | K17: =K12-K15 -> 72398 | L17: =L12-L15 -> 74079
B18: EBITDA Margins | D18: =D17/D7 -> 0.26973365 | E18: =E17/E7 -> 0.26829734 | F18: =F17/F7 -> 0.28351109 | G18: =G17/G7 -> 0.27669305 | H18: =H17/H7 -> 0.26283831 | I18: =I17/I7 -> 0.26690688 | J18: =J17/J7 -> 0.26400573 | K18: =K17/K7 -> 0.27113223 | L18: =L17/L7 -> 0.26853936
B20: Depreciation | D20: =IFERROR('Data Sheet'!D26,0) -> 2056 | E20: =IFERROR('Data Sheet'!E26,0) -> 3529 | F20: =IFERROR('Data Sheet'!F26,0) -> 4065 | G20: =IFERROR('Data Sheet'!G26,0) -> 4604 | H20: =IFERROR('Data Sheet'!H26,0) -> 5022 | I20: =IFERROR('Data Sheet'!I26,0) -> 4985 | J20: =IFERROR('Data Sheet'!J26,0) -> 5242 | K20: =IFERROR('Data Sheet'!K26,0) -> 5560 | L20: =IFERROR(SUM('Data Sheet'!H45:K45),0) -> 5438
B21: Depreciation % Sales | D21: =D20/D7 -> 0.014037675 | E21: =E20/E7 -> 0.022485011 | F21: =F20/F7 -> 0.024759863 | G21: =G20/G7 -> 0.024009929 | H21: =H20/H7 -> 0.022274659 | I21: =I20/I7 -> 0.020693835 | J21: =J20/J7 -> 0.020530777 | K21: =K20/K7 -> 0.020822332 | L21: =L20/L7 -> 0.019712969
B23: EBIT | D23: =D17-D20 -> 37450 | E23: =E17-E20 -> 38580 | F23: =F17-F20 -> 42481 | G23: =G17-G20 -> 48453 | H23: =H17-H20 -> 54237 | I23: =I17-I20 -> 59311 | J23: =J17-J20 -> 62165 | K23: =K17-K20 -> 66838 | L23: =L17-L20 -> 68641
B24: EBIT Margin | D24: =D23/D7 -> 0.25569598 | E24: =E23/E7 -> 0.24581233 | F24: =F23/F7 -> 0.25875123 | G24: =G23/G7 -> 0.25268313 | H24: =H23/H7 -> 0.24056365 | I24: =I23/I7 -> 0.24621305 | J24: =J23/J7 -> 0.24347496 | K24: =K23/K7 -> 0.2503099 | L24: =L23/L7 -> 0.24882639
B26: Interest | D26: =IFERROR('Data Sheet'!D27,0) -> 198 | E26: =IFERROR('Data Sheet'!E27,0) -> 924 | F26: =IFERROR('Data Sheet'!F27,0) -> 637 | G26: =IFERROR('Data Sheet'!G27,0) -> 784 | H26: =IFERROR('Data Sheet'!H27,0) -> 779 | I26: =IFERROR('Data Sheet'!I27,0) -> 778 | J26: =IFERROR('Data Sheet'!J27,0) -> 796 | K26: =IFERROR('Data Sheet'!K27,0) -> 1227 | L26: =IFERROR(SUM('Data Sheet'!H46:K46),0) -> 1305
B27: Interest % Sales | D27: =D26/D7 -> 0.0013518773 | E27: =E26/E7 -> 0.0058872627 | F27: =F26/F7 -> 0.0038799588 | G27: =G26/G7 -> 0.0040885718 | H27: =H26/H7 -> 0.003455189 | I27: =I26/I7 -> 0.0032296497 | J27: =J26/J7 -> 0.0031176074 | K27: =K26/K7 -> 0.0045951442 | L27: =L26/L7 -> 0.0047306776
B29: Other Income | D29: =IFERROR('Data Sheet'!D25,0) -> 4311 | E29: =IFERROR('Data Sheet'!E25,0) -> 4592 | F29: =IFERROR('Data Sheet'!F25,0) -> 1916 | G29: =IFERROR('Data Sheet'!G25,0) -> 4018 | H29: =IFERROR('Data Sheet'!H25,0) -> 3449 | I29: =IFERROR('Data Sheet'!I25,0) -> 3464 | J29: =IFERROR('Data Sheet'!J25,0) -> 3962 | K29: =IFERROR('Data Sheet'!K25,0) -> -124 | L29: =IFERROR(SUM('Data Sheet'!H44:K44),0) -> -884
B30: Other Income % Sales | D30: =D29/D7 -> 0.029434055 | E30: =E29/E7 -> 0.029257912 | F30: =F29/F7 -> 0.011670331 | G30: =G29/G7 -> 0.020953931 | H30: =H29/H7 -> 0.015297749 | I30: =I29/I7 -> 0.014379828 | J30: =J29/J7 -> 0.015517539 | K30: =K29/K7 -> -0.00046438295 | L30: =L29/L7 -> -0.0032045357
B32: EBT | D32: =(D23+D29)-D26 -> 41563 | E32: =(E23+E29)-E26 -> 42248 | F32: =(F23+F29)-F26 -> 43760 | G32: =(G23+G29)-G26 -> 51687 | H32: =(H23+H29)-H26 -> 56907 | I32: =(I23+I29)-I26 -> 61997 | J32: =(J23+J29)-J26 -> 65331 | K32: =(K23+K29)-K26 -> 65487 | L32: =(L23+L29)-L26 -> 66452
B33: EBT Margin | D33: =D32/D7 -> 0.28377816 | E33: =E32/E7 -> 0.26918298 | F33: =F32/F7 -> 0.2665416 | G33: =G32/G7 -> 0.26954848 | H33: =H32/H7 -> 0.25240621 | I33: =I32/I7 -> 0.25736323 | J33: =J32/J7 -> 0.25587489 | K33: =K32/K7 -> 0.24525037 | L33: =L32/L7 -> 0.24089118
B35: TAX | D35: =IFERROR('Data Sheet'!D29,0) -> 10001 | E35: =IFERROR('Data Sheet'!E29,0) -> 9801 | F35: =IFERROR('Data Sheet'!F29,0) -> 11198 | G35: =IFERROR('Data Sheet'!G29,0) -> 13238 | H35: =IFERROR('Data Sheet'!H29,0) -> 14604 | I35: =IFERROR('Data Sheet'!I29,0) -> 15898 | J35: =IFERROR('Data Sheet'!J29,0) -> 16534 | K35: =IFERROR('Data Sheet'!K29,0) -> 16033 | L35: =IFERROR(SUM('Data Sheet'!H48:K48),0) -> 16397
B36: Tax % sales | D36: =D35/D7 -> 0.068283457 | E36: =E35/E7 -> 0.062447037 | F36: =F35/F7 -> 0.068206874 | G36: =G35/G7 -> 0.06903637 | H36: =H35/H7 -> 0.064774814 | I36: =I35/I7 -> 0.065996106 | J36: =J35/J7 -> 0.064756936 | K36: =K35/K7 -> 0.060043967 | L36: =L35/L7 -> 0.059439786
B38: Net Profit | D38: =D32-D35 -> 31562 | E38: =E32-E35 -> 32447 | F38: =F32-F35 -> 32562 | G38: =G32-G35 -> 38449 | H38: =H32-H35 -> 42303 | I38: =I32-I35 -> 46099 | J38: =J32-J35 -> 48797 | K38: =K32-K35 -> 49454 | L38: =L32-L35 -> 50055
B39: Net Margin | D39: =D38/D7 -> 0.2154947 | E39: =E38/E7 -> 0.20673595 | F39: =F38/F7 -> 0.19833472 | G39: =G38/G7 -> 0.20051211 | H39: =H38/H7 -> 0.1876314 | I39: =I38/I7 -> 0.19136712 | J39: =J38/J7 -> 0.19111795 | K39: =K38/K7 -> 0.18520641 | L39: =L38/L7 -> 0.18145139
B41: No of Shares | D41: =IFERROR('Data Sheet'!D93,0) -> 375.24 | E41: =IFERROR('Data Sheet'!E93,0) -> 375.24 | F41: =IFERROR('Data Sheet'!F93,0) -> 369.91 | G41: =IFERROR('Data Sheet'!G93,0) -> 365.91 | H41: =IFERROR('Data Sheet'!H93,0) -> 365.91 | I41: =IFERROR('Data Sheet'!I93,0) -> 361.81 | J41: =IFERROR('Data Sheet'!J93,0) -> 361.81 | K41: =IFERROR('Data Sheet'!K93,0) -> 361.81
B43: EPS | D43: =D38/D41 -> 84.111502 | E43: =E38/E41 -> 86.469993 | F43: =F38/F41 -> 88.026817 | G43: =G38/G41 -> 105.07775 | H43: =H38/H41 -> 115.6104 | I43: =I38/I41 -> 127.41218 | J43: =J38/J41 -> 134.86913 | K43: =K38/K41 -> 136.685
B44: EPS Growth | D44: - | E44: =E43/D43-1 -> 0.028040048 | F44: =F43/E43-1 -> 0.01800422 | G44: =G43/F43-1 -> 0.19370158 | H44: =H43/G43-1 -> 0.10023668 | I44: =I43/H43-1 -> 0.10208236 | J44: =J43/I43-1 -> 0.058526215 | K44: =K43/J43-1 -> 0.013463942
B46: Divident Per Share | D46: =IFERROR('Data Sheet'!D31/'Historicail Financial Statement'!D41,0) -> 29.980812 | E46: =IFERROR('Data Sheet'!E31/'Historicail Financial Statement'!E41,0) -> 72.95331 | F46: =IFERROR('Data Sheet'!F31/'Historicail Financial Statement'!F41,0) -> 38.009245 | G46: =IFERROR('Data Sheet'!G31/'Historicail Financial Statement'!G41,0) -> 43.010576 | H46: =IFERROR('Data Sheet'!H31/'Historicail Financial Statement'!H41,0) -> 115.02829 | I46: =IFERROR('Data Sheet'!I31/'Historicail Financial Statement'!I41,0) -> 73.038335 | J46: =IFERROR('Data Sheet'!J31/'Historicail Financial Statement'!J41,0) -> 126.06617 | K46: =IFERROR('Data Sheet'!K31/'Historicail Financial Statement'!K41,0) -> 110.05777
B47: Divident Pay Out Ratio | D47: =D46/D43 -> 0.35644129 | E47: =E46/E43 -> 0.84368355 | F47: =F46/F43 -> 0.43179166 | G47: =G46/G43 -> 0.40932144 | H47: =H46/H43 -> 0.9949649 | I47: =I46/I43 -> 0.57324454 | J47: =J46/J43 -> 0.93472959 | K47: =K46/K43 -> 0.8051927
B49: Retaind Ernings | D49: =IFERROR(IF(D43>D46,1-D47,0),0) -> 0.64355871 | E49: =IFERROR(IF(E43>E46,1-E47,0),0) -> 0.15631645 | F49: =IFERROR(IF(F43>F46,1-F47,0),0) -> 0.56820834 | G49: =IFERROR(IF(G43>G46,1-G47,0),0) -> 0.59067856 | H49: =IFERROR(IF(H43>H46,1-H47,0),0) -> 0.0050351039 | I49: =IFERROR(IF(I43>I46,1-I47,0),0) -> 0.42675546 | J49: =IFERROR(IF(J43>J46,1-J47,0),0) -> 0.065270406 | K49: =IFERROR(IF(K43>K46,1-K47,0),0) -> 0.1948073
A51: # | B51: ="Balance Sheet - "&'Data Sheet'!B1 -> Balance Sheet - TATA CONSULTANCY SERVICES LTD
B53: Equity Share Capital | D53: =IFERROR('Data Sheet'!D57,0) -> 375 | E53: =IFERROR('Data Sheet'!E57,0) -> 375 | F53: =IFERROR('Data Sheet'!F57,0) -> 370 | G53: =IFERROR('Data Sheet'!G57,0) -> 366 | H53: =IFERROR('Data Sheet'!H57,0) -> 366 | I53: =IFERROR('Data Sheet'!I57,0) -> 362 | J53: =IFERROR('Data Sheet'!J57,0) -> 362 | K53: =IFERROR('Data Sheet'!K57,0) -> 362
B54: Reserves | D54: =IFERROR('Data Sheet'!D58,0) -> 89071 | E54: =IFERROR('Data Sheet'!E58,0) -> 83751 | F54: =IFERROR('Data Sheet'!F58,0) -> 86063 | G54: =IFERROR('Data Sheet'!G58,0) -> 88773 | H54: =IFERROR('Data Sheet'!H58,0) -> 90058 | I54: =IFERROR('Data Sheet'!I58,0) -> 90127 | J54: =IFERROR('Data Sheet'!J58,0) -> 94394 | K54: =IFERROR('Data Sheet'!K58,0) -> 106878
B55: Borrowings | D55: =IFERROR('Data Sheet'!D59,0) -> 62 | E55: =IFERROR('Data Sheet'!E59,0) -> 8174 | F55: =IFERROR('Data Sheet'!F59,0) -> 7795 | G55: =IFERROR('Data Sheet'!G59,0) -> 7818 | H55: =IFERROR('Data Sheet'!H59,0) -> 7688 | I55: =IFERROR('Data Sheet'!I59,0) -> 8021 | J55: =IFERROR('Data Sheet'!J59,0) -> 9392 | K55: =IFERROR('Data Sheet'!K59,0) -> 11283
B56: Other Liabilities | D56: =IFERROR('Data Sheet'!D60,0) -> 24393 | E56: =IFERROR('Data Sheet'!E60,0) -> 27827 | F56: =IFERROR('Data Sheet'!F60,0) -> 35764 | G56: =IFERROR('Data Sheet'!G60,0) -> 43967 | H56: =IFERROR('Data Sheet'!H60,0) -> 44747 | I56: =IFERROR('Data Sheet'!I60,0) -> 46962 | J56: =IFERROR('Data Sheet'!J60,0) -> 54501 | K56: =IFERROR('Data Sheet'!K60,0) -> 62644
B57: Total Liabilities. | D57: =SUM(D53:D56) -> 113901 | E57: =SUM(E53:E56) -> 120127 | F57: =SUM(F53:F56) -> 129992 | G57: =SUM(G53:G56) -> 140924 | H57: =SUM(H53:H56) -> 142859 | I57: =SUM(I53:I56) -> 145472 | J57: =SUM(J53:J56) -> 158649 | K57: =SUM(K53:K56) -> 181167
B59: Fixed Assets &Net Block | D59: =IFERROR('Data Sheet'!D62,0) -> 12290 | E59: =IFERROR('Data Sheet'!E62,0) -> 20928 | F59: =IFERROR('Data Sheet'!F62,0) -> 21021 | G59: =IFERROR('Data Sheet'!G62,0) -> 21298 | H59: =IFERROR('Data Sheet'!H62,0) -> 20515 | I59: =IFERROR('Data Sheet'!I62,0) -> 19604 | J59: =IFERROR('Data Sheet'!J62,0) -> 23053 | K59: =IFERROR('Data Sheet'!K62,0) -> 31343
...

Sheet Ratio Analysis
B5: ="Rario Analysis-"&'Data Sheet'!B1 -> Rario Analysis-TATA CONSULTANCY SERVICES LTD
B6: Years | D6: ='Historicail Financial Statement'!D4 -> 43555 | E6: ='Historicail Financial Statement'!E4 -> 43921 | F6: ='Historicail Financial Statement'!F4 -> 44286 | G6: ='Historicail Financial Statement'!G4 -> 44651 | H6: ='Historicail Financial Statement'!H4 -> 45016 | I6: ='Historicail Financial Statement'!I4 -> 45382 | J6: ='Historicail Financial Statement'!J4 -> 45747 | K6: ='Historicail Financial Statement'!K4 -> 46112 | L6: Trand Lein | M6: Average | N6: Median
B8: SalesGrowth | D8: ='Historicail Financial Statement'!D8 -> - | E8: ='Historicail Financial Statement'!E8 -> 0.071594874 | F8: ='Historicail Financial Statement'!F8 -> 0.046053177 | G8: ='Historicail Financial Statement'!G8 -> 0.16797115 | H8: ='Historicail Financial Statement'!H8 -> 0.17576687 | I8: ='Historicail Financial Statement'!I8 -> 0.068460645 | J8: ='Historicail Financial Statement'!J8 -> 0.059906265 | K8: ='Historicail Financial Statement'!K8 -> 0.04581238 | M8: =AVERAGE(E8:K8) -> 0.090795052 | N8: =MEDIAN(E8:K8) -> 0.068460645
B9: EBITDA Growth | E9: ='Historicail Financial Statement'!E17/'Historicail Financial Statement'!D17-1 -> 0.065888726 | F9: ='Historicail Financial Statement'!F17/'Historicail Financial Statement'!E17-1 -> 0.1053694 | G9: ='Historicail Financial Statement'!G17/'Historicail Financial Statement'!F17-1 -> 0.13988313 | H9: ='Historicail Financial Statement'!H17/'Historicail Financial Statement'!G17-1 -> 0.11689315 | I9: ='Historicail Financial Statement'!I17/'Historicail Financial Statement'!H17-1 -> 0.084999747 | J9: ='Historicail Financial Statement'!J17/'Historicail Financial Statement'!I17-1 -> 0.048385592 | K9: ='Historicail Financial Statement'!K17/'Historicail Financial Statement'!J17-1 -> 0.074042755 | M9: =AVERAGE(E9:K9) -> 0.090780357 | N9: =MEDIAN(E9:K9) -> 0.084999747
B10: EBIT Growth | E10: ='Historicail Financial Statement'!E23/'Historicail Financial Statement'!D23-1 -> 0.030173565 | F10: ='Historicail Financial Statement'!F23/'Historicail Financial Statement'!E23-1 -> 0.10111457 | G10: ='Historicail Financial Statement'!G23/'Historicail Financial Statement'!F23-1 -> 0.14058049 | H10: ='Historicail Financial Statement'!H23/'Historicail Financial Statement'!G23-1 -> 0.11937341 | I10: ='Historicail Financial Statement'!I23/'Historicail Financial Statement'!H23-1 -> 0.093552372 | J10: ='Historicail Financial Statement'!J23/'Historicail Financial Statement'!I23-1 -> 0.048119236 | K10: ='Historicail Financial Statement'!K23/'Historicail Financial Statement'!J23-1 -> 0.075170916 | M10: =AVERAGE(E10:K10) -> 0.086869223 | N10: =MEDIAN(E10:K10) -> 0.093552372
B11: Net Profit Growth | E11: ='Historicail Financial Statement'!E38/'Historicail Financial Statement'!D38-1 -> 0.028040048 | F11: ='Historicail Financial Statement'!F38/'Historicail Financial Statement'!E38-1 -> 0.0035442414 | G11: ='Historicail Financial Statement'!G38/'Historicail Financial Statement'!F38-1 -> 0.18079356 | H11: ='Historicail Financial Statement'!H38/'Historicail Financial Statement'!G38-1 -> 0.10023668 | I11: ='Historicail Financial Statement'!I38/'Historicail Financial Statement'!H38-1 -> 0.089733589 | J11: ='Historicail Financial Statement'!J38/'Historicail Financial Statement'!I38-1 -> 0.058526215 | K11: ='Historicail Financial Statement'!K38/'Historicail Financial Statement'!J38-1 -> 0.013463942 | M11: =AVERAGE(E11:K11) -> 0.067762611 | N11: =MEDIAN(E11:K11) -> 0.058526215
B12: Dividend Growth | E12: ='Historicail Financial Statement'!E46/'Historicail Financial Statement'!D46-1 -> 1.4333333 | F12: ='Historicail Financial Statement'!F46/'Historicail Financial Statement'!E46-1 -> -0.47899217 | G12: ='Historicail Financial Statement'!G46/'Historicail Financial Statement'!F46-1 -> 0.13158196 | H12: ='Historicail Financial Statement'!H46/'Historicail Financial Statement'!G46-1 -> 1.6744186 | I12: ='Historicail Financial Statement'!I46/'Historicail Financial Statement'!H46-1 -> -0.36504022 | J12: ='Historicail Financial Statement'!J46/'Historicail Financial Statement'!I46-1 -> 0.7260274 | K12: ='Historicail Financial Statement'!K46/'Historicail Financial Statement'!J46-1 -> -0.12698413 | M12: =AVERAGE(E12:K12) -> 0.42776354 | N12: =MEDIAN(E12:K12) -> 0.13158196
B14: Gross Margin | D14: ='Historicail Financial Statement'!D13 -> 0.98450121 | E14: ='Historicail Financial Statement'!E13 -> 0.9878623 | F14: ='Historicail Financial Statement'!F13 -> 0.99109498 | G14: ='Historicail Financial Statement'!G13 -> 0.99393494 | H14: ='Historicail Financial Statement'!H13 -> 0.99165698 | I14: ='Historicail Financial Statement'!I13 -> 0.98463218 | J14: ='Historicail Financial Statement'!J13 -> 0.95437953 | K14: ='Historicail Financial Statement'!K13 -> 0.98352564 | M14: =AVERAGE(E14:K14) -> 0.98386951 | N14: =MEDIAN(E14:K14) -> 0.9878623
B15: EBITDA Margin | D15: ='Historicail Financial Statement'!D18 -> 0.26973365 | E15: ='Historicail Financial Statement'!E18 -> 0.26829734 | F15: ='Historicail Financial Statement'!F18 -> 0.28351109 | G15: ='Historicail Financial Statement'!G18 -> 0.27669305 | H15: ='Historicail Financial Statement'!H18 -> 0.26283831 | I15: ='Historicail Financial Statement'!I18 -> 0.26690688 | J15: ='Historicail Financial Statement'!J18 -> 0.26400573 | K15: ='Historicail Financial Statement'!K18 -> 0.27113223 | M15: =AVERAGE(E15:K15) -> 0.27048352 | N15: =MEDIAN(E15:K15) -> 0.26829734
B16: EBIT Margin | D16: ='Historicail Financial Statement'!D24 -> 0.25569598 | E16: ='Historicail Financial Statement'!E24 -> 0.24581233 | F16: ='Historicail Financial Statement'!F24 -> 0.25875123 | G16: ='Historicail Financial Statement'!G24 -> 0.25268313 | H16: ='Historicail Financial Statement'!H24 -> 0.24056365 | I16: ='Historicail Financial Statement'!I24 -> 0.24621305 | J16: ='Historicail Financial Statement'!J24 -> 0.24347496 | K16: ='Historicail Financial Statement'!K24 -> 0.2503099 | M16: =AVERAGE(E16:K16) -> 0.24825832 | N16: =MEDIAN(E16:K16) -> 0.24621305
B17: EBT Margin | D17: ='Historicail Financial Statement'!D33 -> 0.28377816 | E17: ='Historicail Financial Statement'!E33 -> 0.26918298 | F17: ='Historicail Financial Statement'!F33 -> 0.2665416 | G17: ='Historicail Financial Statement'!G33 -> 0.26954848 | H17: ='Historicail Financial Statement'!H33 -> 0.25240621 | I17: ='Historicail Financial Statement'!I33 -> 0.25736323 | J17: ='Historicail Financial Statement'!J33 -> 0.25587489 | K17: ='Historicail Financial Statement'!K33 -> 0.24525037 | M17: =AVERAGE(E17:K17) -> 0.25945254 | N17: =MEDIAN(E17:K17) -> 0.25736323
B18: Net Profit Margin | D18: ='Historicail Financial Statement'!D39 -> 0.2154947 | E18: ='Historicail Financial Statement'!E39 -> 0.20673595 | F18: ='Historicail Financial Statement'!F39 -> 0.19833472 | G18: ='Historicail Financial Statement'!G39 -> 0.20051211 | H18: ='Historicail Financial Statement'!H39 -> 0.1876314 | I18: ='Historicail Financial Statement'!I39 -> 0.19136712 | J18: ='Historicail Financial Statement'!J39 -> 0.19111795 | K18: ='Historicail Financial Statement'!K39 -> 0.18520641 | M18: =AVERAGE(E18:K18) -> 0.19441509 | N18: =MEDIAN(E18:K18) -> 0.19136712
